Workbook

Sheet DESCONTOS
B3: DESCONTO PROF EDUC. INFANTIL E FUNDAMENTAL I
B5: Nº | C5: FUNCIONÁRIOS | D5: AG./APOST/UNIF | E5: MENS./FILHOS/SOBRINHOS | F5: OUTROS | G5: TOTAL DESCONTOS | H5: OBSERVAÇÃO | I5: UNIF.
B6: 1 | C6: Ana Flávia de Jesus Luciano | G6: =SUM(D6:F6) -> 0
B7: 2 | C7: Ângela Maria dos S. Gonçalves | F7: 23.5 | G7: =SUM(D7:F7) -> 23.5 | H7: Cantina
B8: 3 | C8: Carlene R. da Cunha Manrique | G8: =SUM(D8:F8) -> 0
B9: 4 | C9: Carolina Cardoso Miranda | G9: =SUM(D9:F9) -> 0
B10: 5 | C10: Divino Eterno Bruno Alves Correia | G10: =SUM(D10:F10) -> 0
B11: 6 | C11: Elaine Batista Oliveira | E11: 0 | G11: =SUM(D11:F11) -> 0
B12: 7 | C12: Ellizainne Janine Silva | G12: =SUM(D12:F12) -> 0
B13: 8 | C13: Evelyn Emylly Moreira dos Reis | G13: =SUM(D13:F13) -> 0
B14: 9 | C14: Hellen Alves Lemes | E14: 209.5 | F14: 660.43 | G14: =SUM(D14:F14) -> 869.93 | H14: Livros/ conseguinado | J14: desconto credito trabalhista
B15: 10 | C15: Janete de Freitas Rodrigues | G15: =SUM(D15:F15) -> 0
B16: 11 | C16: Lucilene Maria Montelo | G16: =SUM(D16:F16) -> 0
B17: 12 | C17: Maria Angélica de Araújo | G17: =SUM(D17:F17) -> 0
B18: 13 | C18: Maria da Conceição Bezerra da Silva | F18: 33.5 | G18: =SUM(D18:F18) -> 33.5 | H18: Cantina
B19: 14 | C19: Mariana Alves de Deus | G19: =SUM(D19:F19) -> 0
B20: 15 | C20: Mayara Lorrayne da Silva | G20: =SUM(D20:F20) -> 0
B21: 16 | C21: Sthéfanny Guimarães | G21: =SUM(D21:F21) -> 0
B22: 17 | C22: Victória Karoline de Oliveira Menezes | F22: 11.5 | G22: =SUM(D22:F22) -> 11.5 | H22: Cantina
B23: 18 | G23: =SUM(D23:F23) -> 0
B24: 19 | G24: =SUM(D24:F24) -> 0
B25: TOTAL | D25: =SUM(D6:D20) -> 0 | E25: =SUM(E6:E20) -> 209.5 | F25: =SUM(F6:F20) -> 717.43 | G25: =SUM(G6:G20) -> 926.93
B26: DESCONTO ADMINISTRATIVO | I26: =SUM(I6:I25) -> 0
B28: Nº | C28: FUNCIONÁRIOS | D28: AG./APOST/UNIF | E28: MENS./FILHOS/SOBRINHOS | F28: OUTROS | G28: TOTAL DESCONTOS | H28: OBSERVAÇÃO | I28: UNIF.
B29: 1 | C29: Joseane Silva Leite | F29: 30 | G29: =SUM(D29:F29) -> 30
B30: 2 | C30: Keila Regina de Oliveira | G30: =SUM(D30:F30) -> 0
B31: 3 | C31: Luciany Maria da Silva | G31: =SUM(D31:F31) -> 0
B32: 4 | C32: Maria Márcia B. Souza | G32: =SUM(D32:F32) -> 0
B33: 5 | C33: Reginalda Canuto Machado Silva | G33: =SUM(D33:F33) -> 0
B34: 6 | C34: Rossania Brigida R.Ribeiro | F34: 30 | G34: =SUM(D34:F34) -> 30
B35: 7 | C35: Selma dos Reis Teixeira Gonçalves | F35: 365.08 | G35: =SUM(D35:F35) -> 365.08 | H35: Consiguinado
B36: 8 | C36: Solange Jesus Koga Lima | F36: 43.5 | G36: =SUM(D36:F36) -> 43.5 | H36: Cantina
B37: 9 | C37: Wânia Marques Silva | D37: 1099.96 | F37: 164.9 | G37: =SUM(D37:F37) -> 1264.86 | H37: Cantina/sindicato
B38: 10 | G38: =SUM(D38:F38) -> 0
B39: 11 | G39: =SUM(D39:F39) -> 0
B40: TOTAL | D40: =SUM(D29:D33) -> 0 | E40: =SUM(E29:E33) -> 0 | F40: =SUM(F29:F33) -> 30 | G40: =SUM(G29:G34) -> 60 | I40: =SUM(I29:I33) -> 0
B41: DESCONTO FUNDAMENTAL II
B42: Nº | C42: FUNDAMENTAL II | D42: AG./APOST/UNIF | E42: MENS./FILHOS/SOBRINHOS | F42: OUTROS | G42: TOTAL DESCONTOS | H42: OBSERVAÇÃO | I42: UNIF.
B43: 1 | C43: Aurio Velozo dos Santos Godoy | D43: 519.2 | E43: 1068 | G43: =SUM(D43:F43) -> 1587.2 | H43: Mensaliade/cantina
B44: 2 | C44: Elaine Batista Oliveira | G44: =SUM(D44:F44) -> 0 | J44: 230.1
...

Sheet Professores
N3: 01/05/2026 a 31/05/2026
F5: Pagamentos | N5: Deduções | S5: Salário | T5: Saldo a
B6: Nº | C6: Funcionários | D6: Aniv. | E6: Entrada | F6: Salário base | G6: SALÁRIO S/ DSR | H6: DSR | I6: Adicional | J6: Salário dobra | K6: DSR | L6: 1/3 férias | M6: TOTAL SALÁRIO | N6: GPS | O6: IRRF | P6: sindicato | Q6: ADIANT. | R6: Deduções | S6: Família | T6: Receber
B7: 1 | C7: Ana Flávia de Jesus Luciano | D7: 33679 | E7: 41135 | F7: 2917.81 | G7: =F7-H7 -> 2431.5083 | H7: =F7/6 -> 486.30167 | J7: 2457.51 | K7: 460.95 | M7: =SUM(G7:L7) -> 5836.27 | N7: 618.58 | O7: 324.61 | Q7: =DESCONTOS!G6 -> 0 | R7: =N7+O7+Q7+P7 -> 943.19 | T7: =M7-R7+S7 -> 4893.08
B8: 2 | C8: Ângela Maria dos S. Gonçalves | D8: 40913 | E8: 35674 | F8: 2917.81 | G8: =F8-H8 -> 2431.5083 | H8: =F8/6 -> 486.30167 | I8: 235 | J8: 2457.51 | K8: 460.95 | L8: 130 | M8: =SUM(G8:L8) -> 6201.27 | N8: 618.58 | O8: 324.61 | P8: 194.35 | Q8: =DESCONTOS!G7 -> 23.5 | R8: =N8+O8+Q8+P8 -> 1161.04 | T8: =M8-R8+S8 -> 5040.23 | U8: ADICIONAL RAFAELA
B9: 3 | C9: Carlene R. da Cunha Manrique | D9: 41013 | E9: 31413 | F9: 2179.94 | G9: =F9-H9 -> 1816.6167 | H9: =F9/6 -> 363.32333 | I9: 995.5 | J9: 0 | K9: 0 | M9: =SUM(G9:L9) -> 3175.44 | Q9: =DESCONTOS!G8 -> 0 | R9: =N9+O9+Q9+P9 -> 0 | T9: =M9-R9+S9 -> 3175.44 | U9: ,
B10: 4 | C10: Adriane Cristina Siqueira | E10: 46169 | F10: 951.45 | G10: =F10-H10 -> 792.875 | H10: =F10/6 -> 158.575 | M10: =SUM(G10:L10) -> 951.45 | N10: 27.44 | P10: 73.12 | R10: =N10+O10+Q10+P10 -> 100.56 | T10: =M10-R10+S10 -> 850.89
B11: 5 | G11: =F11-H11 -> 0 | H11: =F11/6 -> 0 | I11: 0 | M11: =SUM(G11:L11) -> 0 | Q11: =DESCONTOS!G10 -> 0 | R11: =N11+O11+Q11+P11 -> 0 | T11: =M11-R11+S11 -> 0
B12: 6 | C12: Elaine Batista Oliveira | D12: 41955 | E12: 43214 | F12: 2637.5 | G12: =F12-H12 -> 2197.9167 | H12: =F12/6 -> 439.58333 | I12: 0 | J12: 0 | M12: =SUM(G12:L12) -> 2637.5 | Q12: =DESCONTOS!G11 -> 0 | R12: =N12+O12+Q12+P12 -> 0 | T12: =M12-R12+S12 -> 2637.5
B13: 7 | C13: Ellizainne Janine Silva | D13: 41143 | E13: 43221 | F13: 2181 | G13: =F13-H13 -> 1817.5 | H13: =F13/6 -> 363.5 | I13: 210.97 | J13: 1825.36 | M13: =SUM(G13:L13) -> 4217.33 | N13: 190.93 | P13: 72.62 | Q13: =DESCONTOS!G12 -> 0 | R13: =N13+O13+Q13+P13 -> 263.55 | T13: =M13-R13+S13 -> 3953.78
B14: 8 | C14: Evelyn Emylly Moreira dos Reis | E14: 44618 | F14: 2195.78 | G14: =F14-H14 -> 1829.8167 | H14: =F14/6 -> 365.96333 | J14: 2180 | L14: 200 | M14: =SUM(G14:L14) -> 4575.78 | N14: 173.28 | P14: 65.87 | Q14: =DESCONTOS!G13 -> 0 | R14: =N14+O14+Q14+P14 -> 239.15 | T14: =M14-R14+S14 -> 4336.63 | U14: ADICIONAL RAFAELA
B15: 9 | C15: Hellen Alves Lemes | D15: 42735 | E15: 42374 | F15: 2181 | G15: =F15-H15 -> 1817.5 | H15: =F15/6 -> 363.5 | I15: 199.02 | J15: 0 | M15: =SUM(G15:L15) -> 2380.02 | N15: 189.05 | P15: 72.62 | Q15: =DESCONTOS!G14 -> 869.93 | R15: =N15+O15+Q15+P15 -> 1131.6 | T15: =M15-R15+S15 -> 1248.42
B16: 10 | C16: Janete de Freitas Rodrigues | D16: 44239 | E16: 44249 | F16: 1737 | G16: =F16-H16 -> 1447.5 | H16: =F16/6 -> 289.5 | I16: 1000 | J16: 0 | M16: =SUM(G16:L16) -> 2737 | N16: 132.01 | P16: 52.11 | Q16: =DESCONTOS!G15 -> 0 | R16: =N16+O16+Q16+P16 -> 184.12 | T16: =M16-R16+S16 -> 2552.88
B17: 11 | C17: Lucilene Maria Montelo | D17: 40973 | E17: 39329 | F17: 4185.3643 | G17: =F17-H17 -> 3487.8036 | H17: =F17/6 -> 697.56072 | I17: 0 | M17: =SUM(G17:L17) -> 4185.3643 | N17: 390.83 | P17: 139.37 | Q17: =DESCONTOS!G16 -> 0 | R17: =N17+O17+Q17+P17 -> 530.2 | T17: =M17-R17+S17 -> 3655.1644
B18: 12 | G18: =F18-H18 -> 0 | H18: =F18/6 -> 0 | M18: =SUM(G18:L18) -> 0 | Q18: =DESCONTOS!G17 -> 0 | R18: =N18+O18+Q18+P18 -> 0 | T18: =M18-R18+S18 -> 0
B19: 13 | C19: Maria da Conceição Bezerra da Silva | E19: 45523 | F19: 1737 | G19: =F19-H19 -> 1447.5 | H19: =F19/6 -> 289.5 | J19: 527.5 | M19: =SUM(G19:L19) -> 2264.5 | N19: 132.01 | P19: 52.11 | Q19: =DESCONTOS!G18 -> 33.5 | R19: =N19+O19+Q19+P19 -> 217.62 | T19: =M19-R19+S19 -> 2046.88
B20: 14 | C20: Mariana Alves de Deus | E20: 12/01/206 | F20: 2195.782 | G20: =F20-H20 -> 1829.8184 | H20: =F20/6 -> 365.96367 | M20: =SUM(G20:L20) -> 2195.782 | N20: 173.28 | P20: 73.12 | Q20: =DESCONTOS!G19 -> 0 | R20: =N20+O20+Q20+P20 -> 246.4 | T20: =M20-R20+S20 -> 1949.382
B21: 15 | G21: =F21-H21 -> 0 | H21: =F21/6 -> 0 | M21: =SUM(G21:L21) -> 0 | Q21: =DESCONTOS!G20 -> 0 | R21: =N21+O21+Q21+P21 -> 0 | T21: =M21-R21+S21 -> 0
B22: 16 | C22: Sthéfanny Guimarães | D22: 45757 | E22: 44655 | F22: 2195.78 | G22: =F22-H22 -> 1829.8167 | H22: =F22/6 -> 365.96333 | J22: 1737 | M22: =SUM(G22:L22) -> 3932.78 | N22: 173.28 | O22: 0 | P22: 73.12 | Q22: =DESCONTOS!G21 -> 0 | R22: =N22+O22+Q22+P22 -> 246.4 | T22: =M22-R22+S22 -> 3686.38
B23: 17 | C23: Victória Karoline de Oliveira Menezes | E23: 45869 | F23: 1737 | G23: =F23-H23 -> 1447.5 | H23: =F23/6 -> 289.5 | J23: 1728.05 | L23: 90 | M23: =SUM(G23:L23) -> 3555.05 | N23: 132.01 | P23: 52.11 | Q23: =DESCONTOS!G22 -> 11.5 | R23: =N23+O23+Q23+P23 -> 195.62 | S23: 67.54 | T23: =M23-R23+S23 -> 3426.97 | U23: ADICIONAL RAFAELA
B24: 18 | G24: =F24-H24 -> 0 | H24: =F24/6 -> 0 | M24: =SUM(G24:L24) -> 0 | Q24: =DESCONTOS!G23 -> 0 | R24: =N24+O24+Q24+P24 -> 0 | T24: =M24-R24+S24 -> 0
B25: 19 | G25: =F25-H25 -> 0 | H25: =F25/6 -> 0 | M25: =SUM(G25:L25) -> 0 | Q25: =DESCONTOS!G24 -> 0 | R25: =N25+O25+Q25+P25 -> 0
B26: 20 | G26: =F26-H26 -> 0 | H26: =F26/6 -> 0 | M26: =SUM(G26:L26) -> 0 | Q26: =DESCONTOS!G25 -> 926.93 | R26: =N26+O26+Q26+P26 -> 926.93 | T26: =M26-R26+S26 -> -926.93
B27: 21 | Q27: =DESCONTOS!G26 -> 0
C28: TOTAL = = > | F28: =SUM(F7:F23) -> 31950.216 | G28: =SUM(G7:G23) -> 26625.18 | H28: =SUM(H7:H23) -> 5325.0361 | I28: =SUM(I7:I22) -> 2640.49 | J28: =SUM(J7:J23) -> 12912.93 | K28: =SUM(K7:K22) -> 921.9 | L28: =SUM(L7:L22) -> 330 | M28: =SUM(M7:M22) -> 45290.486 | N28: =SUM(N7:N23) -> 2951.28 | O28: =SUM(O7:O22) -> 649.22 | Q28: =SUM(Q7:Q22) -> 926.93 | R28: =SUM(R7:R22) -> 5263.83 | S28: =SUM(S7:S22) -> 0 | T28: =SUM(T7:T27) -> 42526.696
T31: =SUM(T28+Funcionários!Q17+'F. FUND. II'!S19) -> 83508.576

Sheet Funcionários
D1: FOLHA DE PAGAMENTO
N2: 01/05/2026 a 31/05/2026
F5: Pagamentos | K5: Deduções | P5: Salário | Q5: Saldo a
B6: Nº | C6: Funcionários | D6: Aniversário | E6: Entrada | F6: Salário base | G6: Adicional | H6: Salário dobra | I6: Gratificação | J6: Total | K6: GPS | L6: IRRF | M6: sindicato | N6: =DESCONTOS!G28 -> TOTAL DESCONTOS | O6: Deduções | P6: Família | Q6: Receber
B7: 1 | C7: Joseane Silva Leite | D7: 45026 | E7: 44993 | F7: 1728.05 | G7: 391.73 | H7: 0 | J7: =SUM(F7:I7) -> 2119.78 | N7: =DESCONTOS!G29 -> 30 | O7: =SUM(K7:N7) -> 30 | Q7: =J7-O7+P7 -> 2089.78
B8: 2 | C8: Keila Regina de Oliveira | D8: 45041 | E8: 44959 | F8: 3067.4969 | G8: 0 | J8: =SUM(F8:I8) -> 3067.4969 | K8: 256.68 | M8: 92.03 | N8: =DESCONTOS!G30 -> 0 | O8: =SUM(K8:N8) -> 348.71 | Q8: =J8-O8+P8 -> 2718.7869
B9: 3 | C9: Luciany Maria da Silva | E9: 45919 | F9: 1737 | J9: =SUM(F9:I9) -> 1737 | K9: 132.01 | M9: 52.11 | N9: =DESCONTOS!G31 -> 0 | O9: =SUM(K9:N9) -> 184.12 | Q9: =J9-O9+P9 -> 1552.88
B10: 4 | C10: Maria Márcia B. Souza | D10: 41103 | E10: 34820 | F10: 1737 | G10: 135.26 | H10: 0 | I10: 317.58 | J10: =SUM(F10:I10) -> 2189.84 | K10: 172.13 | M10: 52.11 | N10: =DESCONTOS!G32 -> 0 | O10: =SUM(K10:N10) -> 224.24 | Q10: =J10-O10+P10 -> 1965.6
B11: 5 | C11: Reginalda Canuto Machado Silva | D11: 42159 | E11: 42009 | F11: 1737 | G11: 76.88 | H11: 691.566 | I11: 422 | J11: =SUM(F11:I11) -> 2927.446 | K11: 138.56 | M11: 52.11 | N11: =DESCONTOS!G33 -> 0 | O11: =SUM(K11:N11) -> 190.67 | Q11: =J11-O11+P11 -> 2736.776
B12: 6 | C12: Rossania Brigida R.Ribeiro | D12: 41262 | E12: 40299 | F12: 4648.5727 | G12: 0 | H12: 0 | I12: 0 | J12: =SUM(F12:I12) -> 4648.5727 | K12: 452.3 | M12: 139.46 | N12: =DESCONTOS!G34 -> 30 | O12: =SUM(K12:N12) -> 621.76 | Q12: =J12-O12+P12 -> 4026.8126
B13: 7 | C13: Selma dos Reis Teixeira Gonçalves | D13: 30384 | E13: 44854 | F13: 1737 | G13: 271.46 | H13: 58.74 | J13: =SUM(F13:I13) -> 2067.2 | K13: 161.72 | M13: 52.11 | N13: =DESCONTOS!G35 -> 365.08 | O13: =SUM(K13:N13) -> 578.91 | Q13: =J13-O13+P13 -> 1488.29
B14: 8 | C14: Solange Jesus Koga Lima | D14: 41100 | E14: 39882 | F14: 2180.0309 | G14: 1804.12 | H14: 1677.66 | I14: 0 | J14: =SUM(F14:I14) -> 5661.8109 | K14: 481.87 | M14: 161.83 | N14: =DESCONTOS!G36 -> 43.5 | O14: =SUM(K14:N14) -> 687.2 | Q14: =J14-O14+P14 -> 4974.6109
B15: 9 | C15: Wânia Marques Silva | D15: 40969 | E15: 41672 | F15: 3677.68 | G15: 306.55 | H15: 0 | I15: 0 | J15: =SUM(F15:I15) -> 3984.23 | K15: 366.69 | M15: 122.47 | N15: =DESCONTOS!G37 -> 1264.86 | O15: =SUM(K15:N15) -> 1754.02 | Q15: =J15-O15+P15 -> 2230.21
B16: 10 | J16: =SUM(F16:I16) -> 0 | N16: =DESCONTOS!G38 -> 0 | O16: =SUM(K16:N16) -> 0 | Q16: =J16-O16+P16 -> 0
C17: TOTAL = = > | F17: =SUM(F7:F11) -> 10006.547 | G17: =SUM(G7:G16) -> 2986 | H17: =SUM(H7:H16) -> 2427.966 | I17: =SUM(I7:I16) -> 739.58 | J17: =SUM(J7:J16) -> 28403.376 | K17: =SUM(K7:K16) -> 2161.96 | M17: =SUM(M7:M16) -> 724.23 | N17: =SUM(N7:N16) -> 1733.44 | O17: =SUM(O7:O15) -> 4619.63 | P17: =SUM(P7:P16) -> 0 | Q17: =SUM(Q7:Q16) -> 23783.746
C21: Selma 1 hora extra por dia
I24: 1869.21
I25: 694.26
F28: 15.902 | G28: 0.055 | H28: =F28+(F28*G28) -> 16.77661

Sheet F. FUND. II
P3: 01/05/2026 a 31/05/2026
B5: FOLHA DE PAGAMENTO
F7: Pagamentos | M7: Deduções | R7: Salário | S7: Saldo a
B8: Nº | C8: Funcionários | D8: Aniv. | E8: Entrada | F8: Salário | G8: Salário S/ DSR | H8: DSR | I8: Adicional | J8: Salário dobra | K8: 1/3 férias | L8: Total | M8: INSS | N8: IRRF | O8: SIND | P8: ADIANT | Q8: Deduções | R8: Família | S8: Receber | T8: TOTAL
B9: 1 | C9: Aurio Velozo dos Santos Godoy | D9: 44503 | E9: 43538 | F9: 3344.7509 | G9: =F9-H9 -> 2787.2924 | H9: =F9/6 -> 557.45848 | I9: 0 | L9: =SUM(G9:K9) -> 3344.7509 | P9: =DESCONTOS!G43 -> 1587.2 | Q9: =SUM(M9:P9) -> 1587.2 | S9: =L9-Q9+R9 -> 1757.5509
B10: 2 | C10: Elaine Batista Oliveira | D10: 41955 | E10: 41640 | F10: 2927.625 | G10: =F10-H10 -> 2439.6875 | H10: =F10/6 -> 487.9375 | L10: =SUM(G10:K10) -> 2927.625 | P10: =DESCONTOS!G44 -> 0 | Q10: =SUM(M10:P10) -> 0 | S10: =L10-Q10+R10 -> 2927.625 | T10: =SUM(S10+Professores!T12) -> 5565.125
B11: 3 | C11: Pollyanna Aparecida de Souza | F11: 1655.64 | G11: =F11-H11 -> 1379.7 | H11: =F11/6 -> 275.94 | L11: =SUM(G11:K11) -> 1655.64 | M11: 124.68 | O11: 55.13 | P11: =DESCONTOS!G45 -> 0 | Q11: =SUM(M11:P11) -> 179.81 | S11: =L11-Q11+R11 -> 1475.83
B12: 4 | C12: Jean Divino de Jesus | D12: 44753 | E12: 44484 | F12: 1692.7369 | G12: =F12-H12 -> 1410.6141 | H12: =F12/6 -> 282.12282 | J12: 0 | L12: =SUM(G12:K12) -> 1692.7369 | P12: =DESCONTOS!G46 -> 0 | Q12: =SUM(M12:P12) -> 0 | S12: =L12-Q12+R12 -> 1692.7369
B13: 5 | C13: Maria Angélica de Araújo | D13: 31257 | E13: 43313 | F13: 4753.1 | G13: =F13-H13 -> 3960.9167 | H13: =F13/6 -> 792.18333 | I13: 559.3 | J13: 0 | L13: =SUM(G13:K13) -> 5312.4 | P13: =DESCONTOS!G47 -> 980.9 | Q13: =SUM(M13:P13) -> 980.9 | S13: =L13-Q13+R13 -> 4331.5 | U13: aulas Elaine fund 1
B14: 6 | C14: Pedro Leandro Oliveira Souza | E14: 45545 | F14: 1850.95 | G14: =F14-H14 -> 1542.4583 | H14: =F14/6 -> 308.49167 | L14: =SUM(G14:K14) -> 1850.95 | M14: 142.26 | O14: 61.63 | P14: =DESCONTOS!G48 -> 0 | Q14: =SUM(M14:P14) -> 203.89 | S14: =L14-Q14+R14 -> 1647.06
B15: 7 | C15: Tatiana Vieira da Silva | E15: 46041 | F15: 1737 | G15: =F15-H15 -> 1447.5 | H15: =F15/6 -> 289.5 | L15: =SUM(G15:K15) -> 1737 | M15: 121.58 | O15: 52.11 | P15: =DESCONTOS!G49 -> 117.01 | Q15: =SUM(M15:P15) -> 290.7 | S15: =L15-Q15+R15 -> 1446.3
B16: 8 | C16: Valdirene da Silva Cunha | E16: 46034 | F16: 1737 | G16: =F16-H16 -> 1447.5 | H16: =F16/6 -> 289.5 | I16: 390 | L16: =SUM(G16:K16) -> 2127 | M16: 155.36 | O16: 52.11 | P16: =DESCONTOS!G50 -> 0 | Q16: =SUM(M16:P16) -> 207.47 | S16: =L16-Q16+R16 -> 1919.53
B17: 9 | C17: Caio de Medeiros Rezende | E17: 46121 | F17: 1417.5 | G17: =F17-H17 -> 1181.25 | H17: =F17/6 -> 236.25 | L17: =SUM(G17:K17) -> 1417.5 | P17: =DESCONTOS!G51 -> 0 | Q17: =SUM(M17:P17) -> 0 | S17: =L17-Q17+R17 -> 1417.5
L18: =SUM(G18:K18) -> 0
C19: TOTAIS = = > | F19: =SUM(F9:F16) -> 19698.803 | G19: =SUM(G9:G16) -> 16415.669 | H19: =SUM(H9:H16) -> 3283.1338 | I19: =SUM(I9:I16) -> 949.3 | J19: =SUM(J9:J16) -> 0 | K19: =SUM(K9:K11) -> 0 | L19: =SUM(L9:L16) -> 20648.103 | M19: =SUM(M9:M17) -> 543.88 | O19: =SUM(O9:O11) -> 55.13 | Q19: =SUM(Q9:Q16) -> 3449.97 | R19: =SUM(R9:R11) -> 0 | S19: =SUM(S9:S16) -> 17198.133
K24: 502.5
K25: 4504.64
G26: 4753.1 | H26: 0.055 | I26: =G26+(G26*H26) -> 5014.5205
