Workbook

Sheet DESCONTOS
B1: DESCONTO PROF EDUC. INFANTIL E FUNDAMENTAL I
B3: Nº | C3: FUNCIONÁRIOS | D3: VALE | E3: AG./APOST/UNIF | F3: MENS./FILHOS/SOBRINHOS | G3: OUTROS | H3: TOTAL DESCONTOS
B4: 1 | C4: Carolina Cardoso Miranda | G4: 57 | H4: =SUM(D4:G4) -> 57 | I4: Cantina
B5: 3 | C5: Inês Vieira de Souza | H5: =SUM(D5:G5) -> 0
B6: 4 | C6: Janaína Maria Nunes | G6: 185 | H6: =SUM(D6:G6) -> 185 | I6: Cantina
B7: 5 | C7: Juliana Vieira Jorge | H7: =SUM(D7:G7) -> 0
B8: 6 | C8: Laís Ramos Fernandes | G8: 40 | H8: =SUM(D8:G8) -> 40 | I8: Lembrancinha dia das mães
B9: 7 | C9: Láyslla Roberta dos Santos Gonçalves | G9: 89 | H9: =SUM(D9:G9) -> 89 | I9: Cantina
B10: 8 | C10: Leia Damasceno de Andrade Apolinario | H10: =SUM(D10:G10) -> 0
B11: 9 | C11: Miramar Barbosa Silva | H11: =SUM(D11:G11) -> 0
B12: 10 | C12: Samantha Silva Amorim | D12: 844.08 | G12: 166.5 | H12: =SUM(D12:G12) -> 1010.58 | I12: Cantina/consiguinado
B13: 11 | C13: Suzane dos Santos Martins | H13: =SUM(D13:G13) -> 0
H14: =SUM(D14:G14) -> 0
H15: =SUM(D15:G15) -> 0
B16: TOTAL: | D16: =SUM(D4:D14) -> 844.08 | E16: =SUM(E4:E14) -> 0 | F16: =SUM(F4:F14) -> 0 | H16: =SUM(D16:G16) -> 844.08
B17: Nº
D18: VALE | E18: AG./APOST/UNIF | F18: MENS./FILHOS/SOBRINHOS | G18: OUTROS | H18: TOTAL DESCONTOS
B19: 1 | C19: Benedito Rodrigues borges | H19: =SUM(D19:G19) -> 0
B20: 2 | C20: Bruna Rocha Ferreira | H20: =SUM(D20:G20) -> 0
B21: 3 | C21: Eduarda Lais Silva Candido | G21: 56.5 | H21: =SUM(D21:G21) -> 56.5 | I21: Cantina
B22: 4 | C22: Lucimar Souza Silva | H22: =SUM(D22:G22) -> 0
B23: 5 | C23: Rosângela Maria Dias | H23: =SUM(D23:G23) -> 0
B24: 6 | C24: Selma Luiz de Paula | H24: =SUM(D24:G24) -> 0
B25: 7 | C25: Vanessa Alves Soares | D25: 40 | F25: 345 | G25: 219.5 | H25: =SUM(D25:G25) -> 604.5 | I25: mensalidade/Cantina/Dia das mães
B26: 8 | C26: Any Karolliny Rodrigues Siqueira | G26: 50.5 | H26: =SUM(D26:G26) -> 50.5 | I26: cantina
B27: 9 | C27: Maria de Fátima Silva | H27: =SUM(D27:G27) -> 0
B28: 10 | H28: =SUM(D28:G28) -> 0
B29: 11 | H29: =SUM(D29:G29) -> 0
B30: 12 | H30: =SUM(D30:G30) -> 0
B31: TOTAL: | D31: =SUM(D19:D22) -> 0 | E31: =SUM(E19:E22) -> 0 | F31: =SUM(F19:F22) -> 0 | G31: =SUM(G19:G22) -> 56.5 | H31: =SUM(H19:H22) -> 56.5
D33: VALE | E33: AG./APOST/UNIF | F33: MENS./FILHOS/SOBRINHOS | G33: OUTROS | H33: TOTAL DESCONTOS
B34: 1 | C34: Ana Livia Lourenço Ferreira | H34: =SUM(D34:G34) -> 0
B35: 2 | C35: Carlos Henrique Camilo de Matos | H35: =SUM(D35:G35) -> 0
B36: 3 | C36: Fernando Silva Olimpio | H36: =SUM(D36:G36) -> 0
B37: 4 | C37: Carlos Leonardo Alves Soares | H37: =SUM(D37:G37) -> 0
B38: 5 | C38: Gabriel Ferreira e Silva | H38: =SUM(D38:G38) -> 0
B39: 6 | C39: Haniery Marques Fernandes | H39: =SUM(D39:G39) -> 0
B40: 7 | C40: Jordana Cristina Silava Gaioso | H40: =SUM(D40:G40) -> 0
B41: 8 | C41: Letícia Dias de Castro | H41: =SUM(D41:G41) -> 0
B42: 9 | C42: Pedro Junio Dias Rosa | D42: 1000 | H42: =SUM(D42:G42) -> 1000
...

Sheet PROFESSORES
D2: FOLHA DE PAGAMENTO
J3: 01/05/2026 a 31/05/2026
B6: Pagamentos | K6: Deduções | P6: Salário | Q6: Saldo a
B7: Nº | C7: Funcionários | D7: Aniv. | E7: Entrada | F7: Salário base | G7: Adicional | H7: Salário dobra | I7: desconsiderar | J7: Total | L7: consig | M7: sindicato | N7: ADIANT. | O7: Deduções | P7: Família | Q7: Receber
B8: 1 | C8: Carolina Cardoso Miranda | E8: 46101 | F8: 2180.89 | G8: 0 | H8: 0 | I8: 0 | J8: =SUM(F8:I8) -> 2180.89 | K8: 171.96 | M8: 72.62 | N8: =DESCONTOS!H4 -> 57 | O8: =SUM(K8:N8) -> 301.58 | Q8: =J8-O8+P8 -> 1879.31
B9: 2 | C9: Inês Vieira de Souza | D9: 41051 | E9: 41141 | F9: 2180 | G9: 198.05 | H9: 0 | I9: 0 | J9: =SUM(F9:I9) -> 2378.05 | K9: 189.78 | M9: 72.62 | N9: =DESCONTOS!H5 -> 0 | O9: =SUM(K9:N9) -> 262.4 | Q9: =J9-O9+P9 -> 2115.65
B10: 3 | C10: Janaína Maria Nunes | D10: 44501 | E10: 43221 | F10: 4650 | G10: 0 | I10: 982.99 | J10: =SUM(F10:I10) -> 5632.99 | N10: =DESCONTOS!H6 -> 185 | O10: =SUM(K10:N10) -> 185 | Q10: =J10-O10+P10 -> 5447.99
B11: 4 | C11: Juliana Vieira Jorge | D11: 44732 | E11: 43213 | F11: 1737 | H11: 0 | J11: =SUM(F11:I11) -> 1737 | K11: 132.01 | M11: 52.11 | N11: =DESCONTOS!H7 -> 0 | O11: =SUM(K11:N11) -> 184.12 | P11: 135.08 | Q11: =J11-O11+P11 -> 1687.96 | R11: Prof+monitora
B12: 5 | C12: Laís Ramos Fernandes | E12: 45670 | F12: 2180.89 | H12: 563.33 | I12: 1428 | J12: =SUM(F12:I12) -> 4172.22 | K12: 171.96 | M12: 72.62 | N12: =DESCONTOS!H8 -> 40 | O12: =SUM(K12:N12) -> 284.58 | Q12: =J12-O12+P12 -> 3887.64
B13: 6 | C13: Láyslla Roberta dos Santos Gonçalves | D13: 42267 | E13: 42036 | F13: 2180.89 | H13: 2180.89 | I13: 458.6 | J13: =SUM(F13:I13) -> 4820.38 | K13: 412.15 | M13: 72.62 | N13: =DESCONTOS!H9 -> 89 | O13: =SUM(K13:N13) -> 573.77 | Q13: =J13-O13+P13 -> 4246.61
B14: 7 | C14: Leia Damasceno de Andrade Apolinario | D14: 43254 | E14: 43151 | F14: 2180.89 | G14: 0 | H14: 0 | I14: 0 | J14: =SUM(F14:I14) -> 2180.89 | K14: 171.96 | M14: 72.62 | N14: =DESCONTOS!H10 -> 0 | O14: =SUM(K14:N14) -> 244.58 | Q14: =J14-O14+P14 -> 1936.31
B15: 8 | C15: Miramar Barbosa Silva | E15: 45873 | F15: 1737 | H15: 0 | I15: 443.89 | J15: =SUM(F15:I15) -> 2180.89 | K15: 132.01 | M15: 52.11 | N15: =DESCONTOS!H11 -> 0 | O15: =SUM(K15:N15) -> 184.12 | P15: 67.54 | Q15: =J15-O15+P15 -> 2064.31
B16: 9 | C16: Samantha Silva Amorim | E16: 04/08/205 | F16: 2767.72 | I16: 3500.28 | J16: =SUM(F16:I16) -> 6268 | K16: 224.77 | L16: 844.08 | M16: 92.17 | N16: =DESCONTOS!H12 -> 1010.58 | O16: =SUM(K16:N16) -> 2171.6 | Q16: =J16-O16+P16 -> 4096.4
B17: 10 | C17: Suzane dos Santos Martins | E17: 46063 | F17: 2236.28 | H17: 0 | J17: =SUM(F17:I17) -> 2236.28 | K17: 176.94 | M17: 74.47 | N17: =DESCONTOS!H13 -> 0 | O17: =SUM(K17:N17) -> 251.41 | Q17: =J17-O17+P17 -> 1984.87
N18: =DESCONTOS!H14 -> 0 | O18: =SUM(K18:N18) -> 0 | Q18: =J18-O18+P18 -> 0
G19: 0 | H19: 0 | J19: =SUM(F19:I19) -> 0 | N19: =DESCONTOS!H15 -> 0 | O19: =SUM(K19:N19) -> 0 | Q19: =J19-O19+P19 -> 0
G20: 0 | H20: 0 | I20: 0 | J20: =SUM(F20:I20) -> 0 | O20: =SUM(K20:N20) -> 0 | Q20: =J20-O20+P20 -> 0
N21: =DESCONTOS!H17 -> 0 | O21: =SUM(K21:N21) -> 0 | Q21: =J21-O21+P21 -> 0
C22: TOTAL | F22: =SUM(F8:F18) -> 24031.56 | G22: =SUM(G8:G18) -> 198.05 | H22: =SUM(H8:H17) -> 2744.22 | I22: =SUM(I8:I18) -> 6813.76 | J22: =SUM(J8:J18) -> 33787.59 | K22: =SUM(K8:K18) -> 1783.54 | M22: =SUM(M8:M17) -> 633.96 | N22: =SUM(N8:N17) -> 1381.58 | O22: =SUM(O8:O17) -> 4643.16 | P22: =SUM(P8:P17) -> 202.62 | Q22: =SUM(Q8:Q19) -> 29347.05
H26: 2180.89
H27: 1737
H30: =H26-H27 -> 443.89

Sheet Admin
N2: 01/05/2026 a 31/05/2026
F5: Pagamentos | K5: Deduções | P5: Salário | Q5: Saldo a
B6: Nº | C6: Funcionários | D6: Aniversário | E6: Entrada | F6: Salário base | G6: Adicional | H6: desconsiderar | I6: decênio | J6: Total | K6: INSS | L6: consig | M6: sindicato | N6: ADIANT | O6: Deduções | P6: Família | Q6: Receber
B7: 1 | C7: Benedito Rodrigues borges | D7: 45128 | E7: 45118 | F7: 2123.65 | H7: 300 | J7: =SUM(F7:I7) -> 2423.65 | N7: =DESCONTOS!H19 -> 0 | O7: =SUM(K7:N7) -> 0 | Q7: =J7-O7+P7 -> 2423.65 | R7: 2 diarias
B8: 2 | C8: Bruna Rocha Ferreira | E8: 46034 | F8: 1621 | H8: 121.57 | I8: 48.63 | J8: =SUM(F8:I8) -> 1791.2 | K8: 121.57 | M8: 48.63 | N8: =DESCONTOS!H20 -> 0 | O8: =SUM(K8:N8) -> 170.2 | Q8: =J8-O8+P8 -> 1621
B9: 3 | C9: Eduarda Lais Silva Candido | F9: 1000 | G9: 40 | J9: =SUM(F9:I9) -> 1040 | N9: =DESCONTOS!H21 -> 56.5 | O9: =SUM(K9:N9) -> 56.5 | Q9: =J9-O9+P9 -> 983.5
B10: 4 | C10: Lucimar Souza Silva | D10: 41271 | E10: 36951 | F10: 1737 | G10: 142.86 | H10: 739.41 | I10: 0 | J10: =SUM(F10:I10) -> 2619.27 | K10: 144.76 | M10: 52.11 | N10: =DESCONTOS!H22 -> 0 | O10: =SUM(K10:N10) -> 196.87 | Q10: =J10-O10+P10 -> 2422.4
B11: 5 | C11: Rosângela Maria Dias | D11: 41113 | E11: 34740 | F11: 1737 | G11: 134.73 | H11: 0 | I11: 292.92 | J11: =SUM(F11:I11) -> 2164.65 | K11: 144.13 | L11: 491.98 | M11: 52.11 | N11: =DESCONTOS!H23 -> 0 | O11: =SUM(K11:N11) -> 688.22 | Q11: =J11-O11+P11 -> 1476.43
B12: 6 | C12: Selma Luiz de Paula | D12: 45202 | E12: 45870 | F12: 1737 | G12: 105.5 | J12: =SUM(F12:I12) -> 1842.5 | K12: 141.5 | M12: 52.11 | N12: =DESCONTOS!H24 -> 0 | O12: =SUM(K12:N12) -> 193.61 | Q12: =J12-O12+P12 -> 1648.89
B13: 7 | C13: Vanessa Alves Soares | E13: 45679 | F13: 1000 | G13: 80 | J13: =SUM(F13:I13) -> 1080 | N13: =DESCONTOS!H25 -> 604.5 | O13: =SUM(K13:N13) -> 604.5 | Q13: =J13-O13+P13 -> 475.5
B14: 8 | C14: Any Karolliny Rodrigues Siqueira | E14: 46055 | F14: 1000 | J14: =SUM(F14:I14) -> 1000 | N14: =DESCONTOS!H26 -> 50.5 | O14: =SUM(K14:N14) -> 50.5 | Q14: =J14-O14+P14 -> 949.5
B15: 9 | C15: Maria de Fatima Silva | E15: 46128 | F15: 1000 | J15: =SUM(F15:I15) -> 1000 | N15: =DESCONTOS!H27 -> 0 | O15: =SUM(K15:N15) -> 0 | Q15: =J15-O15+P15 -> 1000 | R15: Monitora
B16: 10 | J16: =SUM(F16:I16) -> 0 | N16: =DESCONTOS!H28 -> 0 | O16: =SUM(K16:N16) -> 0 | Q16: =J16-O16+P16 -> 0
B17: 11 | I17: 0 | J17: =SUM(F17:I17) -> 0 | N17: =DESCONTOS!H29 -> 0 | O17: =SUM(K17:N17) -> 0 | Q17: =J17-O17+P17 -> 0
B18: 12 | J18: =SUM(F18:I18) -> 0 | N18: =DESCONTOS!H30 -> 0 | O18: =SUM(K18:N18) -> 0 | Q18: =J18-O18+P18 -> 0
C19: TOTAL | F19: =SUM(F7:F18) -> 12955.65 | G19: =SUM(G7:G15) -> 503.09 | H19: =SUM(H7:H18) -> 1160.98 | I19: =SUM(I7:I13) -> 341.55 | J19: =SUM(J7:J18) -> 14961.27 | K19: =SUM(K7:K18) -> 551.96 | M19: =SUM(M7:M13) -> 204.96 | N19: =SUM(N7:N13) -> 661 | O19: =SUM(O7:O18) -> 1960.4 | P19: =SUM(P7:P13) -> 0 | Q19: =SUM(Q7:Q18) -> 13000.87

Sheet ENSINO MÉDIO
L3: 01/05/2026 a 31/05/2026
E6: Pagamentos | I6: Deduções | N6: Salário | O6: Saldo a
B7: Funcionários | C7: Aniversário | D7: Entrada | E7: Salário base | F7: Desconsiderar | G7: 1/3 férias | H7: Total | I7: INSS | J7: IR | K7: sindicato | L7: ADIANT | M7: Deduções | N7: Família | O7: Receber
A8: 1 | B8: Ana Livia Lourenço Ferreira | C8: 45302 | D8: 45323 | E8: 1683.78 | H8: =SUM(E8:G8) -> 1683.78 | I8: 127.22 | K8: 56.07 | L8: =DESCONTOS!H34 -> 0 | M8: =SUM(I8:L8) -> 183.29 | O8: =H8-M8+N8 -> 1500.49
A9: 2 | B9: Carlos Henrique Camilo de Matos | C9: 44778 | D9: 44629 | E9: 1131.94 | F9: 171.18 | H9: =SUM(E9:G9) -> 1303.12 | L9: =DESCONTOS!H35 -> 0 | M9: =SUM(I9:L9) -> 0 | O9: =H9-M9+N9 -> 1303.12
A10: 3 | B10: Fernando Silva Olimpio | C10: 44904 | D10: 44585 | E10: 2168.32 | F10: 558.05 | H10: =SUM(E10:G10) -> 2726.37 | I10: 170.82 | K10: 72.21 | L10: =DESCONTOS!H36 -> 0 | M10: =SUM(I10:L10) -> 243.03 | O10: =H10-M10+N10 -> 2483.34
A11: 4 | B11: CARLOS LEONARDO ALVES SOARES | D11: 46091 | E11: 1668.74 | H11: =SUM(E11:G11) -> 1668.74 | I11: 125.86 | K11: 55.57 | L11: =DESCONTOS!H37 -> 0 | M11: =SUM(I11:L11) -> 181.43 | O11: =H11-M11+N11 -> 1487.31
A12: 5 | B12: Gabriel Ferreira e Silva | C12: 45302 | E12: 2103.22 | H12: =SUM(E12:G12) -> 2103.22 | L12: =DESCONTOS!H38 -> 0 | M12: =SUM(I12:L12) -> 0 | O12: =H12-M12+N12 -> 2103.22
A13: 6 | B13: Haniery Marques Fernandes | D13: 44936 | E13: 1996.76 | F13: 94.39 | H13: =SUM(E13:G13) -> 2091.15 | L13: =DESCONTOS!H39 -> 0 | M13: =SUM(I13:L13) -> 0 | O13: =H13-M13+N13 -> 2091.15
A14: 7 | B14: Jordana Cristina Silava Gaioso | E14: 1164.47 | F14: 168.8 | H14: =SUM(E14:G14) -> 1333.27 | L14: =DESCONTOS!H40 -> 0 | M14: =SUM(I14:L14) -> 0 | O14: =H14-M14+N14 -> 1333.27
A15: 8 | B15: Letícia Dias de Castro | C15: 44849 | D15: 44641 | E15: 1131.97 | F15: 171.18 | H15: =SUM(E15:G15) -> 1303.15 | L15: =DESCONTOS!H41 -> 0 | M15: =SUM(I15:L15) -> 0 | O15: =H15-M15+N15 -> 1303.15
A16: 9 | B16: Pedro Junio Dias Rosa | D16: 45302 | E16: 2448.65 | F16: 155.82 | H16: =SUM(E16:G16) -> 2604.47 | L16: =DESCONTOS!H42 -> 1000 | M16: =SUM(I16:L16) -> 1000 | O16: =H16-M16+N16 -> 1604.47
A17: 10 | B17: Renato Dias de Oliveira | D17: 45558 | E17: 1178.07 | F17: 32.1 | H17: =SUM(E17:G17) -> 1210.17 | L17: =DESCONTOS!H43 -> 0 | M17: =SUM(I17:L17) -> 0 | O17: =H17-M17+N17 -> 1210.17
A18: 11 | B18: Ricardo Alves Martins | D18: 45525 | E18: 3155.43 | H18: =SUM(E18:G18) -> 3155.43 | L18: =DESCONTOS!H44 -> 0 | M18: =SUM(I18:L18) -> 0 | O18: =H18-M18+N18 -> 3155.43
A19: 12 | B19: Saillen Christinna Pereira Couto | E19: 1669.87 | H19: =SUM(E19:G19) -> 1669.87 | I19: 125.89 | K19: 55.58 | L19: =DESCONTOS!H45 -> 372.5 | M19: =SUM(I19:L19) -> 553.97 | N19: 67.54 | O19: =H19-M19+N19 -> 1183.44
A20: 13 | B20: Thais Priscilla Souza | D20: 45189 | E20: 1737 | H20: =SUM(E20:G20) -> 1737 | I20: 132.01 | K20: 52.11 | L20: =DESCONTOS!H46 -> 49 | M20: =SUM(I20:L20) -> 233.12 | O20: =H20-M20+N20 -> 1503.88
A21: 14 | B21: Vinicius Ferreira Barbosa | C21: 44971 | D21: 45154 | E21: 1557.7 | F21: 111.83 | H21: =SUM(E21:G21) -> 1669.53 | L21: =DESCONTOS!H47 -> 0 | M21: =SUM(I21:L21) -> 0 | O21: =H21-M21+N21 -> 1669.53
A22: 15 | H22: =SUM(E22:G22) -> 0 | L22: =DESCONTOS!H48 -> 0 | M22: =SUM(I22:L22) -> 0 | O22: =H22-M22+N22 -> 0
A23: 16 | L23: =DESCONTOS!H49 -> 0
A24: 17 | H24: =SUM(E24:G24) -> 0 | L24: =DESCONTOS!H50 -> 0 | M24: =SUM(I24:L24) -> 0 | O24: =H24-M24+N24 -> 0
A25: 18 | L25: =DESCONTOS!H51 -> 0 | M25: =SUM(I25:L25) -> 0 | O25: =H25-M25+N25 -> 0
A26: 19 | H26: =SUM(E26:G26) -> 0 | L26: =DESCONTOS!H52 -> 0 | M26: =SUM(I26:L26) -> 0 | O26: =H26-M26+N26 -> 0
A27: 20 | H27: =SUM(E27:G27) -> 0 | L27: =DESCONTOS!H53 -> 0 | M27: =SUM(I27:L27) -> 0 | O27: =H27-M27+N27 -> 0
A28: 21 | L28: =DESCONTOS!H54 -> 0
B29: TOTAL | E29: =SUM(E8:E24) -> 24795.92 | F29: =SUM(F8:F24) -> 1463.35 | G29: =SUM(G8:G15) -> 0 | H29: =SUM(H8:H24) -> 26259.27 | I29: =SUM(I8:I15) -> 423.9 | K29: =SUM(K8:K15) -> 183.85 | L29: =SUM(L8:L15) -> 0 | M29: =SUM(M8:M15) -> 607.75 | N29: =SUM(N8:N15) -> 0 | O29: =SUM(O8:O24) -> 23931.97
F31: ajuda de custo gasoliana
